Workbook

Sheet README
A1: Kenya Fintech — Data Analyst Dashboard
A3: Purpose: Formula-driven analyst dashboard covering the four levels of analytics —
A4: Descriptive, Diagnostic, Predictive (summary), and Prescriptive KPIs.
A6: Sheet guide:
A7: Dashboard — Executive KPI scorecard + charts (Level 1: Descriptive)
A8: Diagnostic — Root-cause pivot tables (Level 2: Diagnostic)
A9: Prescriptive — Actionable watchlists (Level 4: Prescriptive)
A10: Data_Transactions — Raw transaction records (source for all formulas)
A11: Data_Loans — Raw loan records
A12: Data_Customers — Raw customer records
A13: Data_Fraud — Raw fraud event records
A15: All KPI and pivot cells use SUMIFS / COUNTIFS / AVERAGEIFS formulas referencing the
... A19: fraud events) — see original source workbook README tab for generation details.

Sheet Dashboard
B2: Kenya Fintech — Executive Dashboard
B3: Level 1: Descriptive Analytics — Portfolio Snapshot
B5: Active Customers | D5: =COUNTIF(Data_Customers!$M$2:$M$1001,"Active") -> 738
B6: Total Transactions | D6: =COUNTA(Data_Transactions!$A$2:$A$3016) -> 3015
B7: Transaction Success Rate | D7: =COUNTIF(Data_Transactions!$I$2:$I$3016,"Completed")/COUNTA(Data_Transactions!$A$2:$A$3016) -> 0.67495854
B8: Total Fee Revenue (KES) | D8: =SUM(Data_Fees!$D$2:$D$3016) -> 371094.03
B9: Loan Book Outstanding (KES) | D9: =SUMIFS(Data_Loans!$K$2:$K$501,Data_Loans!$J$2:$J$501,"Active")+SUMIFS(Data_Loans!$K$2:$K$501,Data_Loans!$J$2:$J$501,"Defaulted") -> 25030586
B10: Loan Default Rate | D10: =COUNTIF(Data_Loans!$J$2:$J$501,"Defaulted")/(COUNTIF(Data_Loans!$J$2:$J$501,"Defaulted")+COUNTIF(Data_Loans!$J$2:$J$501,"Paid")) -> 0.38022814
B11: Open Fraud Cases | D11: =COUNTIF(Data_Fraud!$F$2:$F$151,"New") -> 35
B14: Transactions by Status | E14: Channel Usage
B15: Completed | C15: =COUNTIF(Data_Transactions!$I$2:$I$3016,"Completed") -> 2035 | E15: Agent | F15: =COUNTIF(Data_Transactions!$F$2:$F$3016,"Agent") -> 782
B16: Failed | C16: =COUNTIF(Data_Transactions!$I$2:$I$3016,"Failed") -> 492 | E16: USSD | F16: =COUNTIF(Data_Transactions!$F$2:$F$3016,"USSD") -> 766
B17: Reversed | C17: =COUNTIF(Data_Transactions!$I$2:$I$3016,"Reversed") -> 488 | E17: Mobile | F17: =COUNTIF(Data_Transactions!$F$2:$F$3016,"Mobile") -> 753
E18: App | F18: =COUNTIF(Data_Transactions!$F$2:$F$3016,"App") -> 714
B20: Value by Transaction Type (KES) | E20: Loan Book by Status
B21: Bill Payment | C21: =SUMIFS(Data_Transactions!$G$2:$G$3016,Data_Transactions!$E$2:$E$3016,"Bill Payment") -> 3888387.3 | E21: Active | F21: =COUNTIF(Data_Loans!$J$2:$J$501,"Active") -> 164
B22: Merchant Payment | C22: =SUMIFS(Data_Transactions!$G$2:$G$3016,Data_Transactions!$E$2:$E$3016,"Merchant Payment") -> 3969092.3 | E22: Paid | F22: =COUNTIF(Data_Loans!$J$2:$J$501,"Paid") -> 163
B23: Payment | C23: =SUMIFS(Data_Transactions!$G$2:$G$3016,Data_Transactions!$E$2:$E$3016,"Payment") -> 4421961.5 | E23: Defaulted | F23: =COUNTIF(Data_Loans!$J$2:$J$501,"Defaulted") -> 100
B24: Transfer | C24: =SUMIFS(Data_Transactions!$G$2:$G$3016,Data_Transactions!$E$2:$E$3016,"Transfer") -> 4686509.1 | E24: Rejected | F24: =COUNTIF(Data_Loans!$J$2:$J$501,"Rejected") -> 73
B25: Withdrawal | C25: =SUMIFS(Data_Transactions!$G$2:$G$3016,Data_Transactions!$E$2:$E$3016,"Withdrawal") -> 3735044.5

Sheet Diagnostic
B2: Diagnostic Analytics — Root-Cause Views
B3: Level 2: Why is it happening?
B6: Channel | C6: Completed | D6: Failed | E6: Reversed | F6: Fail/Reversal Rate
B7: Agent | C7: =COUNTIFS(Data_Transactions!$F$2:$F$3016,"Agent",Data_Transactions!$I$2:$I$3016,"Completed") -> 536 | D7: =COUNTIFS(Data_Transactions!$F$2:$F$3016,"Agent",Data_Transactions!$I$2:$I$3016,"Failed") -> 131 | E7: =COUNTIFS(Data_Transactions!$F$2:$F$3016,"Agent",Data_Transactions!$I$2:$I$3016,"Reversed") -> 115 | F7: =(D7+E7)/(C7+D7+E7) -> 0.31457801
B8: USSD | C8: =COUNTIFS(Data_Transactions!$F$2:$F$3016,"USSD",Data_Transactions!$I$2:$I$3016,"Completed") -> 520 | D8: =COUNTIFS(Data_Transactions!$F$2:$F$3016,"USSD",Data_Transactions!$I$2:$I$3016,"Failed") -> 139 | E8: =COUNTIFS(Data_Transactions!$F$2:$F$3016,"USSD",Data_Transactions!$I$2:$I$3016,"Reversed") -> 107 | F8: =(D8+E8)/(C8+D8+E8) -> 0.32114883
B9: Mobile | C9: =COUNTIFS(Data_Transactions!$F$2:$F$3016,"Mobile",Data_Transactions!$I$2:$I$3016,"Completed") -> 496 | D9: =COUNTIFS(Data_Transactions!$F$2:$F$3016,"Mobile",Data_Transactions!$I$2:$I$3016,"Failed") -> 115 | E9: =COUNTIFS(Data_Transactions!$F$2:$F$3016,"Mobile",Data_Transactions!$I$2:$I$3016,"Reversed") -> 142 | F9: =(D9+E9)/(C9+D9+E9) -> 0.34130146
B10: App | C10: =COUNTIFS(Data_Transactions!$F$2:$F$3016,"App",Data_Transactions!$I$2:$I$3016,"Completed") -> 483 | D10: =COUNTIFS(Data_Transactions!$F$2:$F$3016,"App",Data_Transactions!$I$2:$I$3016,"Failed") -> 107 | E10: =COUNTIFS(Data_Transactions!$F$2:$F$3016,"App",Data_Transactions!$I$2:$I$3016,"Reversed") -> 124 | F10: =(D10+E10)/(C10+D10+E10) -> 0.32352941
B13: Loan Default Rate by Product
B14: Loan Product | C14: Total Decided | D14: Defaults | E14: Default Rate
B15: Business Loan | C15: =COUNTIFS(Data_Loans!$E$2:$E$501,"Business Loan",Data_Loans!$J$2:$J$501,"Paid")+COUNTIFS(Data_Loans!$E$2:$E$501,"Business Loan",Data_Loans!$J$2:$J$501,"Defaulted") -> 89 | D15: =COUNTIFS(Data_Loans!$E$2:$E$501,"Business Loan",Data_Loans!$J$2:$J$501,"Defaulted") -> 38 | E15: =D15/C15 -> 0.42696629
B16: Mobile Credit | C16: =COUNTIFS(Data_Loans!$E$2:$E$501,"Mobile Credit",Data_Loans!$J$2:$J$501,"Paid")+COUNTIFS(Data_Loans!$E$2:$E$501,"Mobile Credit",Data_Loans!$J$2:$J$501,"Defaulted") -> 86 | D16: =COUNTIFS(Data_Loans!$E$2:$E$501,"Mobile Credit",Data_Loans!$J$2:$J$501,"Defaulted") -> 30 | E16: =D16/C16 -> 0.34883721
B17: Salary Advance | C17: =COUNTIFS(Data_Loans!$E$2:$E$501,"Salary Advance",Data_Loans!$J$2:$J$501,"Paid")+COUNTIFS(Data_Loans!$E$2:$E$501,"Salary Advance",Data_Loans!$J$2:$J$501,"Defaulted") -> 88 | D17: =COUNTIFS(Data_Loans!$E$2:$E$501,"Salary Advance",Data_Loans!$J$2:$J$501,"Defaulted") -> 32 | E17: =D17/C17 -> 0.36363636
B20: Loan Default Rate by Customer Income Band
B21: Income Band | C21: Total Decided | D21: Defaults | E21: Default Rate
B22: 20K-30K | C22: =SUMPRODUCT((Data_Loans!$J$2:$J$501<>"")*((Data_Loans!$J$2:$J$501="Paid")+(Data_Loans!$J$2:$J$501="Defaulted"))*(IFERROR(VLOOKUP(Data_Loans!$B$2:$B$501,Data_Customers!$A$2:$J$1001,9,0),"")="20K-30K")) -> 0 | D22: =SUMPRODUCT((Data_Loans!$J$2:$J$501="Defaulted")*(IFERROR(VLOOKUP(Data_Loans!$B$2:$B$501,Data_Customers!$A$2:$J$1001,9,0),"")="20K-30K")) -> 0 | E22: =IFERROR(D22/C22,0) -> 0
B23: 30K-50K | C23: =SUMPRODUCT((Data_Loans!$J$2:$J$501<>"")*((Data_Loans!$J$2:$J$501="Paid")+(Data_Loans!$J$2:$J$501="Defaulted"))*(IFERROR(VLOOKUP(Data_Loans!$B$2:$B$501,Data_Customers!$A$2:$J$1001,9,0),"")="30K-50K")) -> 0 | D23: =SUMPRODUCT((Data_Loans!$J$2:$J$501="Defaulted")*(IFERROR(VLOOKUP(Data_Loans!$B$2:$B$501,Data_Customers!$A$2:$J$1001,9,0),"")="30K-50K")) -> 0 | E23: =IFERROR(D23/C23,0) -> 0
B24: 50K-100K | C24: =SUMPRODUCT((Data_Loans!$J$2:$J$501<>"")*((Data_Loans!$J$2:$J$501="Paid")+(Data_Loans!$J$2:$J$501="Defaulted"))*(IFERROR(VLOOKUP(Data_Loans!$B$2:$B$501,Data_Customers!$A$2:$J$1001,9,0),"")="50K-100K")) -> 0 | D24: =SUMPRODUCT((Data_Loans!$J$2:$J$501="Defaulted")*(IFERROR(VLOOKUP(Data_Loans!$B$2:$B$501,Data_Customers!$A$2:$J$1001,9,0),"")="50K-100K")) -> 0 | E24: =IFERROR(D24/C24,0) -> 0
B25: 100K-250K | C25: =SUMPRODUCT((Data_Loans!$J$2:$J$501<>"")*((Data_Loans!$J$2:$J$501="Paid")+(Data_Loans!$J$2:$J$501="Defaulted"))*(IFERROR(VLOOKUP(Data_Loans!$B$2:$B$501,Data_Customers!$A$2:$J$1001,9,0),"")="100K-250K")) -> 0 | D25: =SUMPRODUCT((Data_Loans!$J$2:$J$501="Defaulted")*(IFERROR(VLOOKUP(Data_Loans!$B$2:$B$501,Data_Customers!$A$2:$J$1001,9,0),"")="100K-250K")) -> 0 | E25: =IFERROR(D25/C25,0) -> 0
B26: 250K+ | C26: =SUMPRODUCT((Data_Loans!$J$2:$J$501<>"")*((Data_Loans!$J$2:$J$501="Paid")+(Data_Loans!$J$2:$J$501="Defaulted"))*(IFERROR(VLOOKUP(Data_Loans!$B$2:$B$501,Data_Customers!$A$2:$J$1001,9,0),"")="250K+")) -> 0 | D26: =SUMPRODUCT((Data_Loans!$J$2:$J$501="Defaulted")*(IFERROR(VLOOKUP(Data_Loans!$B$2:$B$501,Data_Customers!$A$2:$J$1001,9,0),"")="250K+")) -> 0 | E26: =IFERROR(D26/C26,0) -> 0

Sheet Prescriptive
B2: Prescriptive Analytics — Action Lists
B3: Level 4: What should we do next?
B5: Note: These are ranked watchlists best generated dynamically. Sort/filter the raw data sheets directly, or use the SQL prescriptive queries (see /sql/05_prescriptive_kpis.sql) for the collections and fraud-triage worklists — a static Excel snapshot below shows the top loan and fraud items as of the data extract date.
B8: Top 10 Overdue Active Loans (Collections Priority)
B9: Loan ID | C9: Customer ID | D9: Product | E9: Outstanding (KES) | F9: Days Past Due
B10: =INDEX(Data_Loans!$A$2:$A$501,MATCH(G10,Data_Loans!$M$2:$M$501,0)) -> LOAN455 | C10: =INDEX(Data_Loans!$B$2:$B$501,MATCH(G10,Data_Loans!$M$2:$M$501,0)) -> CUS656 | D10: =INDEX(Data_Loans!$E$2:$E$501,MATCH(G10,Data_Loans!$M$2:$M$501,0)) -> Business Loan | E10: =INDEX(Data_Loans!$K$2:$K$501,MATCH(G10,Data_Loans!$M$2:$M$501,0)) -> 129280.7 | F10: =INDEX(Data_Loans!$L$2:$L$501,MATCH(G10,Data_Loans!$M$2:$M$501,0)) -> 90 | G10: =LARGE(Data_Loans!$M$2:$M$501,1) -> 90.000449
B11: =INDEX(Data_Loans!$A$2:$A$501,MATCH(G11,Data_Loans!$M$2:$M$501,0)) -> LOAN443 | C11: =INDEX(Data_Loans!$B$2:$B$501,MATCH(G11,Data_Loans!$M$2:$M$501,0)) -> CUS167 | D11: =INDEX(Data_Loans!$E$2:$E$501,MATCH(G11,Data_Loans!$M$2:$M$501,0)) -> Mobile Credit | E11: =INDEX(Data_Loans!$K$2:$K$501,MATCH(G11,Data_Loans!$M$2:$M$501,0)) -> 62431.11 | F11: =INDEX(Data_Loans!$L$2:$L$501,MATCH(G11,Data_Loans!$M$2:$M$501,0)) -> 90 | G11: =LARGE(Data_Loans!$M$2:$M$501,2) -> 90.000437
B12: =INDEX(Data_Loans!$A$2:$A$501,MATCH(G12,Data_Loans!$M$2:$M$501,0)) -> LOAN426 | C12: =INDEX(Data_Loans!$B$2:$B$501,MATCH(G12,Data_Loans!$M$2:$M$501,0)) -> CUS147 | D12: =INDEX(Data_Loans!$E$2:$E$501,MATCH(G12,Data_Loans!$M$2:$M$501,0)) -> Salary Advance | E12: =INDEX(Data_Loans!$K$2:$K$501,MATCH(G12,Data_Loans!$M$2:$M$501,0)) -> 13206.11 | F12: =INDEX(Data_Loans!$L$2:$L$501,MATCH(G12,Data_Loans!$M$2:$M$501,0)) -> 90 | G12: =LARGE(Data_Loans!$M$2:$M$501,3) -> 90.00042
B13: =INDEX(Data_Loans!$A$2:$A$501,MATCH(G13,Data_Loans!$M$2:$M$501,0)) -> LOAN422 | C13: =INDEX(Data_Loans!$B$2:$B$501,MATCH(G13,Data_Loans!$M$2:$M$501,0)) -> CUS442 | D13: =INDEX(Data_Loans!$E$2:$E$501,MATCH(G13,Data_Loans!$M$2:$M$501,0)) -> Salary Advance | E13: =INDEX(Data_Loans!$K$2:$K$501,MATCH(G13,Data_Loans!$M$2:$M$501,0)) -> 18909.36 | F13: =INDEX(Data_Loans!$L$2:$L$501,MATCH(G13,Data_Loans!$M$2:$M$501,0)) -> 90 | G13: =LARGE(Data_Loans!$M$2:$M$501,4) -> 90.000416
B14: =INDEX(Data_Loans!$A$2:$A$501,MATCH(G14,Data_Loans!$M$2:$M$501,0)) -> LOAN399 | C14: =INDEX(Data_Loans!$B$2:$B$501,MATCH(G14,Data_Loans!$M$2:$M$501,0)) -> CUS392 | D14: =INDEX(Data_Loans!$E$2:$E$501,MATCH(G14,Data_Loans!$M$2:$M$501,0)) -> Business Loan | E14: =INDEX(Data_Loans!$K$2:$K$501,MATCH(G14,Data_Loans!$M$2:$M$501,0)) -> 3152.26 | F14: =INDEX(Data_Loans!$L$2:$L$501,MATCH(G14,Data_Loans!$M$2:$M$501,0)) -> 90 | G14: =LARGE(Data_Loans!$M$2:$M$501,5) -> 90.000393
B15: =INDEX(Data_Loans!$A$2:$A$501,MATCH(G15,Data_Loans!$M$2:$M$501,0)) -> LOAN393 | C15: =INDEX(Data_Loans!$B$2:$B$501,MATCH(G15,Data_Loans!$M$2:$M$501,0)) -> CUS706 | D15: =INDEX(Data_Loans!$E$2:$E$501,MATCH(G15,Data_Loans!$M$2:$M$501,0)) -> Salary Advance | E15: =INDEX(Data_Loans!$K$2:$K$501,MATCH(G15,Data_Loans!$M$2:$M$501,0)) -> 11482.44 | F15: =INDEX(Data_Loans!$L$2:$L$501,MATCH(G15,Data_Loans!$M$2:$M$501,0)) -> 90 | G15: =LARGE(Data_Loans!$M$2:$M$501,6) -> 90.000387
B16: =INDEX(Data_Loans!$A$2:$A$501,MATCH(G16,Data_Loans!$M$2:$M$501,0)) -> LOAN314 | C16: =INDEX(Data_Loans!$B$2:$B$501,MATCH(G16,Data_Loans!$M$2:$M$501,0)) -> CUS286 | D16: =INDEX(Data_Loans!$E$2:$E$501,MATCH(G16,Data_Loans!$M$2:$M$501,0)) -> Business Loan | E16: =INDEX(Data_Loans!$K$2:$K$501,MATCH(G16,Data_Loans!$M$2:$M$501,0)) -> 47258.85 | F16: =INDEX(Data_Loans!$L$2:$L$501,MATCH(G16,Data_Loans!$M$2:$M$501,0)) -> 90 | G16: =LARGE(Data_Loans!$M$2:$M$501,7) -> 90.000308
B17: =INDEX(Data_Loans!$A$2:$A$501,MATCH(G17,Data_Loans!$M$2:$M$501,0)) -> LOAN309 | C17: =INDEX(Data_Loans!$B$2:$B$501,MATCH(G17,Data_Loans!$M$2:$M$501,0)) -> CUS811 | D17: =INDEX(Data_Loans!$E$2:$E$501,MATCH(G17,Data_Loans!$M$2:$M$501,0)) -> Mobile Credit | E17: =INDEX(Data_Loans!$K$2:$K$501,MATCH(G17,Data_Loans!$M$2:$M$501,0)) -> 24776.7 | F17: =INDEX(Data_Loans!$L$2:$L$501,MATCH(G17,Data_Loans!$M$2:$M$501,0)) -> 90 | G17: =LARGE(Data_Loans!$M$2:$M$501,8) -> 90.000303
B18: =INDEX(Data_Loans!$A$2:$A$501,MATCH(G18,Data_Loans!$M$2:$M$501,0)) -> LOAN264 | C18: =INDEX(Data_Loans!$B$2:$B$501,MATCH(G18,Data_Loans!$M$2:$M$501,0)) -> CUS210 | D18: =INDEX(Data_Loans!$E$2:$E$501,MATCH(G18,Data_Loans!$M$2:$M$501,0)) -> Mobile Credit | E18: =INDEX(Data_Loans!$K$2:$K$501,MATCH(G18,Data_Loans!$M$2:$M$501,0)) -> 121603.11 | F18: =INDEX(Data_Loans!$L$2:$L$501,MATCH(G18,Data_Loans!$M$2:$M$501,0)) -> 90 | G18: =LARGE(Data_Loans!$M$2:$M$501,9) -> 90.000258
B19: =INDEX(Data_Loans!$A$2:$A$501,MATCH(G19,Data_Loans!$M$2:$M$501,0)) -> LOAN247 | C19: =INDEX(Data_Loans!$B$2:$B$501,MATCH(G19,Data_Loans!$M$2:$M$501,0)) -> CUS492 | D19: =INDEX(Data_Loans!$E$2:$E$501,MATCH(G19,Data_Loans!$M$2:$M$501,0)) -> Salary Advance | E19: =INDEX(Data_Loans!$K$2:$K$501,MATCH(G19,Data_Loans!$M$2:$M$501,0)) -> 25584.73 | F19: =INDEX(Data_Loans!$L$2:$L$501,MATCH(G19,Data_Loans!$M$2:$M$501,0)) -> 90 | G19: =LARGE(Data_Loans!$M$2:$M$501,10) -> 90.000241

Sheet Data_Transactions
A1: transaction_id | B1: account_id | C1: customer_id | D1: transaction_date | E1: transaction_type | F1: channel | G1: amount_kes | H1: fee_kes | I1: status | J1: reference_number | K1: recipient_type | L1: merchant_id | M1: agent_id
A2: TXN001 | B2: ACC001 | C2: CUS001 | D2: 45659.385 | E2: Payment | F2: Mobile | G2: 2500 | H2: 25 | I2: Completed | J2: REF001 | K2: Merchant | L2: MER018
A3: TXN002 | B3: ACC002 | C3: CUS002 | D3: 45659.472 | E3: Transfer | F3: Mobile | G3: 15000 | H3: 75 | I3: Completed | J3: REF002 | K3: Individual | L3: MER035
A4: TXN003 | B4: ACC003 | C4: CUS003 | D4: 45660.365 | E4: Bill Payment | F4: Mobile | G4: 3200 | H4: 20 | I4: Completed | J4: REF003 | K4: Utility | L4: MER052
A5: TXN004 | B5: ACC004 | C5: CUS004 | D5: 45660.646 | E5: Merchant Payment | F5: USSD | G5: 8500 | H5: 50 | I5: Completed | J5: REF004 | K5: Merchant | L5: MER069
A6: TXN005 | B6: ACC005 | C6: CUS005 | D6: 45661.715 | E6: Withdrawal | F6: Agent | G6: 5000 | H6: 60 | I6: Completed | J6: REF005 | K6: Individual | M6: AGT066
A7: TXN006 | B7: ACC006 | C7: CUS006 | D7: 45662.559 | E7: Payment | F7: Mobile | G7: 1200 | H7: 15 | I7: Completed | J7: REF006 | K7: Merchant | L7: MER103
A8: TXN007 | B8: ACC007 | C8: CUS007 | D8: 45663.42 | E8: Transfer | F8: Mobile | G8: 50000 | H8: 100 | I8: Completed | J8: REF007 | K8: Business | L8: MER120
A9: TXN008 | B9: ACC008 | C9: CUS008 | D9: 45664.778 | E9: Payment | F9: Mobile | G9: 750 | H9: 10 | I9: Completed | J9: REF008 | K9: Merchant | L9: MER137
A10: TXN009 | B10: ACC009 | C10: CUS009 | D10: 45665.51 | E10: Payment | F10: App | G10: 22000 | H10: 100 | I10: Completed | J10: REF009 | K10: Merchant | L10: MER004
A11: TXN010 | B11: ACC010 | C11: CUS010 | D11: 45666.618 | E11: Transfer | F11: Mobile | G11: 12000 | H11: 50 | I11: Completed | J11: REF010 | K11: Individual | L11: MER021
A12: TXN011 | B12: ACC001 | C12: CUS001 | D12: 45667.375 | E12: Payment | F12: App | G12: 4500 | H12: 35 | I12: Completed | J12: REF011 | K12: Merchant | L12: MER038
A13: TXN012 | B13: ACC002 | C13: CUS002 | D13: 45667.688 | E13: Withdrawal | F13: Agent | G13: 10000 | H13: 75 | I13: Failed | J13: REF012 | K13: Individual | M13: AGT057
A14: TXN013 | B14: ACC007 | C14: CUS007 | D14: 45668.49 | E14: Merchant Payment | F14: App | G14: 35000 | H14: 100 | I14: Completed | J14: REF013 | K14: Merchant | L14: MER072
A15: TXN014 | B15: ACC009 | C15: CUS009 | D15: 45669.542 | E15: Transfer | F15: Mobile | G15: 75000 | H15: 150 | I15: Completed | J15: REF014 | K15: Business | L15: MER089
A16: TXN015 | B16: ACC004 | C16: CUS004 | D16: 45670.434 | E16: Bill Payment | F16: USSD | G16: 4200 | H16: 25 | I16: Completed | J16: REF015 | K16: Utility | L16: MER106
A17: TXN0016 | B17: ACC372 | C17: CUS372 | D17: 45930.734 | E17: Transfer | F17: USSD | G17: 14101.36 | H17: 75.95 | I17: Completed | J17: REF0016 | K17: Merchant | L17: MER123
A18: TXN0017 | B18: ACC822 | C18: CUS822 | D18: 45867.54 | E18: Withdrawal | F18: Agent | G18: 8780.1 | H18: 27.96 | I18: Completed | J18: REF0017 | K18: Business | M18: AGT022
A19: TXN0018 | B19: ACC717 | C19: CUS717 | D19: 45579.588 | E19: Payment | F19: App | G19: 5593.9 | H19: 36.08 | I19: Completed | J19: REF0018 | K19: Business | L19: MER007
A20: TXN0019 | B20: ACC389 | C20: CUS389 | D20: 45780.534 | E20: Merchant Payment | F20: USSD | G20: 4807.82 | H20: 52.6 | I20: Completed | J20: REF0019 | K20: Merchant | L20: MER024
A21: TXN0020 | B21: ACC908 | C21: CUS908 | D21: 45670.383 | E21: Transfer | F21: Mobile | G21: 1644.52 | H21: 9.76 | I21: Reversed | J21: REF0020 | K21: Individual | L21: MER041
A22: TXN0021 | B22: ACC985 | C22: CUS985 | D22: 45941.721 | E22: Payment | F22: Agent | G22: 664.62 | H22: 6.64 | I22: Completed | J22: REF0021 | K22: Utility | M22: AGT074
A23: TXN0022 | B23: ACC872 | C23: CUS872 | D23: 45550.564 | E23: Merchant Payment | F23: USSD | G23: 1833.33 | H23: 20.46 | I23: Completed | J23: REF0022 | K23: Merchant | L23: MER075
A24: TXN0023 | B24: ACC665 | C24: CUS665 | D24: 45536.678 | E24: Merchant Payment | F24: Mobile | G24: 3447.82 | H24: 8.29 | I24: Completed | J24: REF0023 | K24: Merchant | L24: MER092
A25: TXN0024 | B25: ACC134 | C25: CUS134 | D25: 45931.324 | E25: Merchant Payment | F25: Agent | G25: 4823.26 | H25: 19.28 | I25: Completed | J25: REF0024 | K25: Merchant | M25: AGT013
A26: TXN0025 | B26: ACC712 | C26: CUS712 | D26: 45980.656 | E26: Merchant Payment | F26: Agent | G26: 2869.02 | H26: 20.44 | I26: Reversed | J26: REF0025 | K26: Utility | M26: AGT026
A27: TXN0026 | B27: ACC136 | C27: CUS136 | D27: 45646.649 | E27: Merchant Payment | F27: Mobile | G27: 1932.59 | H27: 5.48 | I27: Reversed | J27: REF0026 | K27: Utility | L27: MER143
A28: TXN0027 | B28: ACC883 | C28: CUS883 | D28: 45813.417 | E28: Payment | F28: Mobile | G28: 3112.72 | H28: 31.17 | I28: Completed | J28: REF0027 | K28: Merchant | L28: MER010
A29: TXN0028 | B29: ACC755 | C29: CUS755 | D29: 45641.381 | E29: Payment | F29: App | G29: 1692.91 | H29: 13.76 | I29: Completed | J29: REF0028 | K29: Merchant | L29: MER027
A30: TXN0029 | B30: ACC191 | C30: CUS191 | D30: 45385.375 | E30: Payment | F30: Agent | G30: 2791.25 | H30: 11.45 | I30: Completed | J30: REF0029 | K30: Individual | M30: AGT078
A31: TXN0030 | B31: ACC488 | C31: CUS488 | D31: 45494.943 | E31: Withdrawal | F31: Mobile | G31: 7837.57 | H31: 73.01 | I31: Completed | J31: REF0030 | K31: Individual | M31: AGT091
A32: TXN0031 | B32: ACC520 | C32: CUS520 | D32: 45298.383 | E32: Withdrawal | F32: App | G32: 12138.93 | H32: 130.88 | I32: Reversed | J32: REF0031 | K32: Merchant | M32: AGT004
A33: TXN0032 | B33: ACC720 | C33: CUS720 | D33: 45369.549 | E33: Bill Payment | F33: Agent | G33: 1860.01 | H33: 19.27 | I33: Failed | J33: REF0032 | K33: Utility | M33: AGT017
A34: TXN0033 | B34: ACC224 | C34: CUS224 | D34: 45728.661 | E34: Bill Payment | F34: USSD | G34: 2833.37 | H34: 5.86 | I34: Completed | J34: REF0033 | K34: Merchant | L34: MER112
A35: TXN0034 | B35: ACC064 | C35: CUS064 | D35: 45356.932 | E35: Merchant Payment | F35: Mobile | G35: 8686.78 | H35: 75.93 | I35: Reversed | J35: REF0034 | K35: Merchant | L35: MER129
A36: TXN0035 | B36: ACC327 | C36: CUS327 | D36: 45894.781 | E36: Bill Payment | F36: USSD | G36: 10565.35 | H36: 28.09 | I36: Completed | J36: REF0035 | K36: Utility | L36: MER146
A37: TXN0036 | B37: ACC761 | C37: CUS761 | D37: 45783.772 | E37: Transfer | F37: App | G37: 2057.56 | H37: 15.35 | I37: Failed | J37: REF0036 | K37: Individual | L37: MER013
A38: TXN0037 | B38: ACC044 | C38: CUS044 | D38: 45999.768 | E38: Merchant Payment | F38: Agent | G38: 3598.58 | H38: 40.43 | I38: Completed | J38: REF0037 | K38: Business | M38: AGT082
A39: TXN0038 | B39: ACC157 | C39: CUS157 | D39: 45437.81 | E39: Transfer | F39: Agent | G39: 8950.85 | H39: 95.8 | I39: Completed | J39: REF0038 | K39: Merchant | M39: AGT095
A40: TXN0039 | B40: ACC445 | C40: CUS445 | D40: 45969.506 | E40: Merchant Payment | F40: Agent | G40: 4892.05 | H40: 14.42 | I40: Completed | J40: REF0039 | K40: Utility | M40: AGT008
...

Sheet Data_Loans
A1: loan_id | B1: customer_id | C1: application_date | D1: approval_date | E1: loan_product | F1: requested_amount | G1: approved_amount | H1: interest_rate | I1: term_days | J1: loan_status | K1: outstanding_balance | L1: days_past_due | M1: dpd_rank_key
A2: LOAN008 | B2: CUS698 | C2: 45753 | D2: 45755 | E2: Mobile Credit | F2: 139348.46 | G2: 112379.63 | H2: 17.034 | I2: 30 | J2: Paid | K2: 0 | L2: 0 | M2: =IF(J2="Active",L2+(ROW()/1000000),"")
A3: LOAN009 | B3: CUS673 | C3: 45488 | D3: 45492 | E3: Mobile Credit | F3: 397699.36 | G3: 392476.19 | H3: 13.228 | I3: 30 | J3: Active | K3: 229830.58 | L3: 1 | M3: =IF(J3="Active",L3+(ROW()/1000000),"") -> 1.000003
A4: LOAN010 | B4: CUS883 | C4: 45704 | D4: 45707 | E4: Business Loan | F4: 414918.05 | G4: 341170.45 | H4: 13.114 | I4: 90 | J4: Paid | K4: 0 | L4: 0 | M4: =IF(J4="Active",L4+(ROW()/1000000),"")
A5: LOAN011 | B5: CUS034 | C5: 45450 | D5: 45452 | E5: Salary Advance | F5: 284697.31 | G5: 216103.07 | H5: 10.509 | I5: 120 | J5: Defaulted | K5: 73422.53 | L5: 15 | M5: =IF(J5="Active",L5+(ROW()/1000000),"")
A6: LOAN012 | B6: CUS990 | C6: 45424 | E6: Mobile Credit | F6: 12056.42 | G6: 0 | H6: 9.618 | I6: 120 | J6: Rejected | K6: 0 | L6: 0 | M6: =IF(J6="Active",L6+(ROW()/1000000),"")
A7: LOAN013 | B7: CUS328 | C7: 45721 | D7: 45721 | E7: Salary Advance | F7: 495392.38 | G7: 282218.42 | H7: 12.981 | I7: 30 | J7: Active | K7: 154932.61 | L7: 10 | M7: =IF(J7="Active",L7+(ROW()/1000000),"") -> 10.000007
A8: LOAN014 | B8: CUS884 | C8: 45830 | E8: Mobile Credit | F8: 258171.49 | G8: 0 | H8: 14.689 | I8: 30 | J8: Rejected | K8: 0 | L8: 0 | M8: =IF(J8="Active",L8+(ROW()/1000000),"")
A9: LOAN015 | B9: CUS001 | C9: 45632 | D9: 45635 | E9: Salary Advance | F9: 230751.99 | G9: 142881.48 | H9: 8.763 | I9: 60 | J9: Active | K9: 118411.61 | L9: 30 | M9: =IF(J9="Active",L9+(ROW()/1000000),"") -> 30.000009
A10: LOAN016 | B10: CUS053 | C10: 45487 | D10: 45491 | E10: Salary Advance | F10: 229880.17 | G10: 132787.15 | H10: 15.117 | I10: 60 | J10: Active | K10: 14111.16 | L10: 15 | M10: =IF(J10="Active",L10+(ROW()/1000000),"") -> 15.00001
A11: LOAN017 | B11: CUS210 | C11: 46016 | E11: Salary Advance | F11: 236351.63 | G11: 0 | H11: 11.307 | I11: 30 | J11: Rejected | K11: 0 | L11: 0 | M11: =IF(J11="Active",L11+(ROW()/1000000),"")
A12: LOAN018 | B12: CUS376 | C12: 45567 | D12: 45567 | E12: Mobile Credit | F12: 177456.52 | G12: 175689.78 | H12: 11.899 | I12: 60 | J12: Active | K12: 163037.51 | L12: 60 | M12: =IF(J12="Active",L12+(ROW()/1000000),"") -> 60.000012
A13: LOAN019 | B13: CUS466 | C13: 45429 | E13: Salary Advance | F13: 333260.89 | G13: 0 | H13: 13.538 | I13: 60 | J13: Rejected | K13: 0 | L13: 0 | M13: =IF(J13="Active",L13+(ROW()/1000000),"")
A14: LOAN020 | B14: CUS679 | C14: 45864 | D14: 45865 | E14: Business Loan | F14: 112246.72 | G14: 88907.48 | H14: 13.421 | I14: 120 | J14: Paid | K14: 0 | L14: 0 | M14: =IF(J14="Active",L14+(ROW()/1000000),"")
A15: LOAN021 | B15: CUS206 | C15: 45864 | E15: Salary Advance | F15: 386822.5 | G15: 0 | H15: 16.02 | I15: 120 | J15: Rejected | K15: 0 | L15: 0 | M15: =IF(J15="Active",L15+(ROW()/1000000),"")
A16: LOAN022 | B16: CUS661 | C16: 45962 | D16: 45962 | E16: Mobile Credit | F16: 309803.99 | G16: 219346.29 | H16: 13.703 | I16: 60 | J16: Paid | K16: 0 | L16: 0 | M16: =IF(J16="Active",L16+(ROW()/1000000),"")
A17: LOAN023 | B17: CUS963 | C17: 45537 | D17: 45539 | E17: Business Loan | F17: 184805.11 | G17: 145259.23 | H17: 16.298 | I17: 60 | J17: Paid | K17: 0 | L17: 0 | M17: =IF(J17="Active",L17+(ROW()/1000000),"")
A18: LOAN024 | B18: CUS914 | C18: 45819 | D18: 45820 | E18: Mobile Credit | F18: 114427.43 | G18: 83532.14 | H18: 16.762 | I18: 30 | J18: Defaulted | K18: 52865.44 | L18: 90 | M18: =IF(J18="Active",L18+(ROW()/1000000),"")
A19: LOAN025 | B19: CUS679 | C19: 45906 | D19: 45910 | E19: Mobile Credit | F19: 178321.65 | G19: 175113.89 | H19: 14.68 | I19: 60 | J19: Active | K19: 85705.07 | L19: 3 | M19: =IF(J19="Active",L19+(ROW()/1000000),"") -> 3.000019
A20: LOAN026 | B20: CUS602 | C20: 45711 | D20: 45716 | E20: Business Loan | F20: 139577.58 | G20: 113523.18 | H20: 7.709 | I20: 120 | J20: Active | K20: 83121.39 | L20: 90 | M20: =IF(J20="Active",L20+(ROW()/1000000),"") -> 90.00002
A21: LOAN027 | B21: CUS580 | C21: 45627 | D21: 45628 | E21: Salary Advance | F21: 331027.28 | G21: 279200.73 | H21: 14.505 | I21: 30 | J21: Defaulted | K21: 130604.9 | L21: 60 | M21: =IF(J21="Active",L21+(ROW()/1000000),"")
A22: LOAN028 | B22: CUS282 | C22: 45628 | D22: 45628 | E22: Salary Advance | F22: 461458.18 | G22: 270596.65 | H22: 17.476 | I22: 30 | J22: Paid | K22: 0 | L22: 0 | M22: =IF(J22="Active",L22+(ROW()/1000000),"")
A23: LOAN029 | B23: CUS485 | C23: 45933 | D23: 45937 | E23: Business Loan | F23: 259094.93 | G23: 181815.77 | H23: 13.456 | I23: 30 | J23: Active | K23: 58320.39 | L23: 30 | M23: =IF(J23="Active",L23+(ROW()/1000000),"") -> 30.000023
A24: LOAN030 | B24: CUS862 | C24: 45337 | E24: Business Loan | F24: 435031.25 | G24: 0 | H24: 9.022 | I24: 180 | J24: Rejected | K24: 0 | L24: 0 | M24: =IF(J24="Active",L24+(ROW()/1000000),"")
A25: LOAN031 | B25: CUS994 | C25: 45699 | D25: 45702 | E25: Salary Advance | F25: 368834.49 | G25: 342326.73 | H25: 9.039 | I25: 30 | J25: Paid | K25: 0 | L25: 0 | M25: =IF(J25="Active",L25+(ROW()/1000000),"")
A26: LOAN032 | B26: CUS849 | C26: 45349 | E26: Mobile Credit | F26: 320678.63 | G26: 0 | H26: 10.91 | I26: 30 | J26: Rejected | K26: 0 | L26: 0 | M26: =IF(J26="Active",L26+(ROW()/1000000),"")
A27: LOAN033 | B27: CUS083 | C27: 45875 | D27: 45880 | E27: Salary Advance | F27: 146186.18 | G27: 94238.13 | H27: 17.938 | I27: 120 | J27: Paid | K27: 0 | L27: 0 | M27: =IF(J27="Active",L27+(ROW()/1000000),"")
A28: LOAN034 | B28: CUS330 | C28: 45994 | D28: 45996 | E28: Salary Advance | F28: 330509.93 | G28: 273532.81 | H28: 11.638 | I28: 30 | J28: Active | K28: 98323.85 | L28: 10 | M28: =IF(J28="Active",L28+(ROW()/1000000),"") -> 10.000028
A29: LOAN035 | B29: CUS720 | C29: 45996 | E29: Salary Advance | F29: 137924.88 | G29: 0 | H29: 15.018 | I29: 30 | J29: Rejected | K29: 0 | L29: 0 | M29: =IF(J29="Active",L29+(ROW()/1000000),"")
A30: LOAN036 | B30: CUS107 | C30: 45639 | D30: 45640 | E30: Business Loan | F30: 328389.34 | G30: 197049.63 | H30: 14.741 | I30: 90 | J30: Defaulted | K30: 77275.42 | L30: 1 | M30: =IF(J30="Active",L30+(ROW()/1000000),"")
A31: LOAN037 | B31: CUS636 | C31: 45953 | D31: 45953 | E31: Mobile Credit | F31: 146294.4 | G31: 112291.68 | H31: 13.294 | I31: 30 | J31: Defaulted | K31: 6086.42 | L31: 10 | M31: =IF(J31="Active",L31+(ROW()/1000000),"")
A32: LOAN038 | B32: CUS403 | C32: 45958 | D32: 45960 | E32: Business Loan | F32: 452552.99 | G32: 311682 | H32: 7.557 | I32: 90 | J32: Paid | K32: 0 | L32: 0 | M32: =IF(J32="Active",L32+(ROW()/1000000),"")
A33: LOAN039 | B33: CUS829 | C33: 45776 | D33: 45778 | E33: Business Loan | F33: 244872.54 | G33: 152237.51 | H33: 12.039 | I33: 60 | J33: Defaulted | K33: 80593.37 | L33: 30 | M33: =IF(J33="Active",L33+(ROW()/1000000),"")
A34: LOAN040 | B34: CUS976 | C34: 45347 | D34: 45348 | E34: Mobile Credit | F34: 268055.76 | G34: 187635.08 | H34: 17.392 | I34: 30 | J34: Defaulted | K34: 122418.16 | L34: 90 | M34: =IF(J34="Active",L34+(ROW()/1000000),"")
A35: LOAN041 | B35: CUS880 | C35: 45982 | D35: 45985 | E35: Business Loan | F35: 23292.01 | G35: 20051.09 | H35: 13.903 | I35: 30 | J35: Active | K35: 5511.27 | L35: 30 | M35: =IF(J35="Active",L35+(ROW()/1000000),"") -> 30.000035
A36: LOAN042 | B36: CUS518 | C36: 45306 | D36: 45311 | E36: Mobile Credit | F36: 445241.57 | G36: 271854.09 | H36: 8.726 | I36: 30 | J36: Paid | K36: 0 | L36: 0 | M36: =IF(J36="Active",L36+(ROW()/1000000),"")
A37: LOAN043 | B37: CUS324 | C37: 45869 | D37: 45870 | E37: Business Loan | F37: 438438.12 | G37: 331244.1 | H37: 17.919 | I37: 60 | J37: Paid | K37: 0 | L37: 0 | M37: =IF(J37="Active",L37+(ROW()/1000000),"")
A38: LOAN044 | B38: CUS954 | C38: 45805 | D38: 45807 | E38: Salary Advance | F38: 192182.42 | G38: 188511.24 | H38: 10.93 | I38: 60 | J38: Paid | K38: 0 | L38: 0 | M38: =IF(J38="Active",L38+(ROW()/1000000),"")
A39: LOAN045 | B39: CUS340 | C39: 45813 | D39: 45817 | E39: Business Loan | F39: 280937.14 | G39: 273443.88 | H39: 7.269 | I39: 120 | J39: Paid | K39: 0 | L39: 0 | M39: =IF(J39="Active",L39+(ROW()/1000000),"")
A40: LOAN046 | B40: CUS781 | C40: 45685 | D40: 45689 | E40: Mobile Credit | F40: 492951.87 | G40: 382251.53 | H40: 14.236 | I40: 90 | J40: Paid | K40: 0 | L40: 0 | M40: =IF(J40="Active",L40+(ROW()/1000000),"")
...

Sheet Data_Customers
A1: customer_id | B1: first_name | C1: last_name | D1: gender | E1: date_of_birth | F1: phone_number | G1: county_id | H1: customer_type | I1: occupation | J1: income_band | K1: registration_date | L1: kyc_status | M1: customer_status
A2: CUS001 | B2: Brian | C2: Mwangi | D2: Male | E2: 35167 | F2: 254700000001 | G2: 1 | H2: Individual | I2: Software Developer | J2: 100K-250K | K2: 45306 | L2: Verified | M2: Active
A3: CUS002 | B3: Wanjiku | C3: Kamau | D3: Female | E3: 34566 | F3: 254700000002 | G3: 5 | H3: Individual | I3: Business Owner | J3: 50K-100K | K3: 45332 | L3: Verified | M3: Active
A4: CUS003 | B4: Kevin | C4: Otieno | D4: Male | E4: 35800 | F4: 254700000003 | G4: 3 | H4: Individual | I4: Teacher | J4: 30K-50K | K4: 45355 | L4: Verified | M4: Active
A5: CUS004 | B5: Amina | C5: Hassan | D5: Female | E5: 33560 | F5: 254700000004 | G5: 2 | H5: Individual | I5: Trader | J5: 50K-100K | K5: 45319 | L5: Verified | M5: Active
A6: CUS005 | B6: David | C6: Kiptoo | D6: Male | E6: 32354 | F6: 254700000005 | G6: 7 | H6: Individual | I6: Farmer | J6: 30K-50K | K6: 45394 | L6: Verified | M6: Active
A7: CUS006 | B7: Faith | C7: Njeri | D7: Female | E7: 36230 | F7: 254700000006 | G7: 6 | H7: Individual | I7: Freelancer | J7: 50K-100K | K7: 45433 | L7: Verified | M7: Active
A8: CUS007 | B8: Samuel | C8: Omondi | D8: Male | E8: 31292 | F8: 254700000007 | G8: 4 | H8: Individual | I8: Business Owner | J8: 100K-250K | K8: 45336 | L8: Verified | M8: Active
A9: CUS008 | B9: Mercy | C9: Achieng | D9: Female | E9: 35604 | F9: 254700000008 | G9: 8 | H9: Individual | I9: Retail Worker | J9: 30K-50K | K9: 45444 | L9: Verified | M9: Active
A10: CUS009 | B10: John | C10: Kamau | D10: Male | E10: 33226 | F10: 254700000009 | G10: 11 | H10: Individual | I10: Engineer | J10: 100K-250K | K10: 45300 | L10: Verified | M10: Active
A11: CUS010 | B11: Grace | C11: Muthoni | D11: Female | E11: 34834 | F11: 254700000010 | G11: 14 | H11: Individual | I11: Entrepreneur | J11: 50K-100K | K11: 45366 | L11: Verified | M11: Active
A12: CUS011 | B12: John | C12: Omondi | D12: Male | E12: 28149 | F12: 254723756669 | G12: 11 | H12: Individual | I12: Driver | J12: 100K-250K | K12: 45208 | L12: Verified | M12: Active
A13: CUS012 | B13: Joseph | C13: Mwangi | D13: Male | E13: 27492 | F13: 254797226012 | G13: 12 | H13: SME | I13: Trader | J13: 100K-250K | K13: 45444 | L13: Verified | M13: Active
... A1001: CUS1000 | B1001: James | C1001: Maina | D1001: Female | E1001: 37061 | F1001: 254794694930 | G1001: 11 | H1001: Individual | I1001: Software Developer | J1001: 250K+ | K1001: 45299 | L1001: Pending | M1001: Active

Sheet Data_Fraud
A1: fraud_event_id | B1: transaction_id | C1: detected_at | D1: fraud_type | E1: risk_score | F1: investigation_status | G1: confirmed_fraud
A2: FRD0003 | B2: TXN2383 | C2: 45475.333 | D2: Velocity anomaly | E2: 0.903 | F2: Confirmed | G2: =FALSE() -> FALSE
A3: FRD0004 | B3: TXN1087 | C3: 45687.708 | D3: Velocity anomaly | E3: 0.821 | F3: Closed | G3: =FALSE() -> FALSE
A4: FRD0005 | B4: TXN1417 | C4: 45439.208 | D4: New beneficiary risk | E4: 0.636 | F4: Investigating | G4: =FALSE() -> FALSE
A5: FRD0006 | B5: TXN0355 | C5: 45855.583 | D5: New beneficiary risk | E5: 0.727 | F5: Confirmed | G5: =FALSE() -> FALSE
A6: FRD0007 | B6: TXN2569 | C6: 45361.333 | D6: Multiple failed attempts | E6: 0.694 | F6: Confirmed | G6: =FALSE() -> FALSE
A7: FRD0008 | B7: TXN1808 | C7: 45599.583 | D7: New beneficiary risk | E7: 0.859 | F7: Investigating | G7: =FALSE() -> FALSE
A8: FRD0009 | B8: TXN2700 | C8: 45371 | D8: Velocity anomaly | E8: 0.828 | F8: New | G8: =FALSE() -> FALSE
A9: FRD0010 | B9: TXN1798 | C9: 45475.625 | D9: New beneficiary risk | E9: 0.804 | F9: Confirmed | G9: =FALSE() -> FALSE
A10: FRD0011 | B10: TXN1679 | C10: 45975.708 | D10: New beneficiary risk | E10: 0.978 | F10: Confirmed | G10: =FALSE() -> FALSE
A11: FRD0012 | B11: TXN2992 | C11: 45470 | D11: Multiple failed attempts | E11: 0.905 | F11: New | G11: =FALSE() -> FALSE
A12: FRD0013 | B12: TXN1329 | C12: 45773.708 | D12: Multiple failed attempts | E12: 0.859 | F12: Confirmed | G12: =FALSE() -> FALSE
A13: FRD0014 | B13: TXN0286 | C13: 45706.25 | D13: Multiple failed attempts | E13: 0.668 | F13: Confirmed | G13: =FALSE() -> FALSE
... A23: FRD0024 | B23: TXN3013 | C23: 45907.458 | D23: New beneficiary risk | E23: 0.868 | F23: Confirmed | G23: =FALSE() -> FALSE
A24: FRD0025 | B24: TXN0802 | C24: 45616.125 | D24: New beneficiary risk | E24: 0.977 | F24: Investigating | G24: =TRUE() -> TRUE
A25: FRD0026 | B25: TXN0737 | C25: 45454.583 | D25: Unusual transaction amount | E25: 0.967 | F25: New | G25: =TRUE() -> TRUE
A26: FRD0027 | B26: TXN0206 | C26: 45353.167 | D26: Unusual transaction amount | E26: 0.631 | F26: Closed | G26: =FALSE() -> FALSE
A27: FRD0028 | B27: TXN0211 | C27: 45324.958 | D27: Multiple failed attempts | E27: 0.834 | F27: Confirmed | G27: =FALSE() -> FALSE
A28: FRD0029 | B28: TXN1291 | C28: 45632.458 | D28: New beneficiary risk | E28: 0.98 | F28: Confirmed | G28: =TRUE() -> TRUE
A29: FRD0030 | B29: TXN0888 | C29: 45445.708 | D29: Velocity anomaly | E29: 0.868 | F29: Investigating | G29: =FALSE() -> FALSE
A30: FRD0031 | B30: TXN0280 | C30: 45484.167 | D30: Unusual transaction amount | E30: 0.945 | F30: Investigating | G30: =FALSE() -> FALSE
A31: FRD0032 | B31: TXN2976 | C31: 45560.792 | D31: Velocity anomaly | E31: 0.826 | F31: Closed | G31: =FALSE() -> FALSE
A32: FRD0033 | B32: TXN2627 | C32: 45302.667 | D32: Multiple failed attempts | E32: 0.829 | F32: Confirmed | G32: =FALSE() -> FALSE
A33: FRD0034 | B33: TXN2037 | C33: 45503.167 | D33: New beneficiary risk | E33: 0.834 | F33: Closed | G33: =FALSE() -> FALSE
A34: FRD0035 | B34: TXN1372 | C34: 45729.167 | D34: New beneficiary risk | E34: 0.799 | F34: New | G34: =FALSE() -> FALSE
A35: FRD0036 | B35: TXN0777 | C35: 45769.042 | D35: Velocity anomaly | E35: 0.951 | F35: Closed | G35: =FALSE() -> FALSE
A36: FRD0037 | B36: TXN2500 | C36: 45829.333 | D36: Multiple failed attempts | E36: 0.753 | F36: New | G36: =FALSE() -> FALSE
A37: FRD0038 | B37: TXN1555 | C37: 45700 | D37: Multiple failed attempts | E37: 0.835 | F37: Confirmed | G37: =FALSE() -> FALSE
A38: FRD0039 | B38: TXN0224 | C38: 45718.167 | D38: New beneficiary risk | E38: 0.805 | F38: Closed | G38: =FALSE() -> FALSE
A39: FRD0040 | B39: TXN1359 | C39: 45806.708 | D39: New beneficiary risk | E39: 0.758 | F39: Investigating | G39: =FALSE() -> FALSE
A40: FRD0041 | B40: TXN1098 | C40: 45599.5 | D40: Velocity anomaly | E40: 0.985 | F40: New | G40: =TRUE() -> TRUE
A41: FRD0042 | B41: TXN1148 | C41: 45435.875 | D41: Unusual transaction amount | E41: 0.807 | F41: Investigating | G41: =FALSE() -> FALSE
A42: FRD0043 | B42: TXN2400 | C42: 45543.875 | D42: Unusual transaction amount | E42: 0.779 | F42: New | G42: =FALSE() -> FALSE
A43: FRD0044 | B43: TXN0587 | C43: 45433.042 | D43: Velocity anomaly | E43: 0.867 | F43: New | G43: =FALSE() -> FALSE
A44: FRD0045 | B44: TXN0395 | C44: 45433.833 | D44: Multiple failed attempts | E44: 0.733 | F44: New | G44: =FALSE() -> FALSE
A45: FRD0046 | B45: TXN2088 | C45: 45577.042 | D45: Multiple failed attempts | E45: 0.682 | F45: Closed | G45: =FALSE() -> FALSE
A46: FRD0047 | B46: TXN2929 | C46: 45689.875 | D46: Multiple failed attempts | E46: 0.928 | F46: Investigating | G46: =FALSE() -> FALSE
A47: FRD0048 | B47: TXN006 | C47: 45842.583 | D47: New beneficiary risk | E47: 0.791 | F47: Confirmed | G47: =FALSE() -> FALSE
A48: FRD0049 | B48: TXN2517 | C48: 45347.042 | D48: Velocity anomaly | E48: 0.745 | F48: Investigating | G48: =FALSE() -> FALSE
A49: FRD0050 | B49: TXN2972 | C49: 45733 | D49: New beneficiary risk | E49: 0.662 | F49: Investigating | G49: =FALSE() -> FALSE
...

Sheet Data_Fees
A1: fee_id | B1: transaction_id | C1: fee_type | D1: fee_amount | E1: fee_date
A2: FEE0001 | B2: TXN001 | C2: Withdrawal Fee | D2: 25 | E2: 45299
A3: FEE0002 | B3: TXN002 | C3: Transaction Fee | D3: 5.74 | E3: 45306
A4: FEE0003 | B4: TXN003 | C4: Transfer Fee | D4: 6.11 | E4: 45313
A5: FEE0004 | B5: TXN004 | C5: Transfer Fee | D5: 6.48 | E5: 45320
A6: FEE0005 | B6: TXN005 | C6: Withdrawal Fee | D6: 6.85 | E6: 45327
A7: FEE0006 | B7: TXN006 | C7: Transaction Fee | D7: 7.22 | E7: 45334
A8: FEE0007 | B8: TXN007 | C8: Merchant Fee | D8: 7.59 | E8: 45341
A9: FEE0008 | B9: TXN008 | C9: Transaction Fee | D9: 7.96 | E9: 45348
A10: FEE0009 | B10: TXN009 | C10: Withdrawal Fee | D10: 8.33 | E10: 45355
A11: FEE0010 | B11: TXN010 | C11: Withdrawal Fee | D11: 8.7 | E11: 45362
A12: FEE0011 | B12: TXN011 | C12: Merchant Fee | D12: 9.07 | E12: 45369
A13: FEE0012 | B13: TXN012 | C13: Bill Payment Fee | D13: 9.44 | E13: 45376
... A3016: FEE3015 | B3016: TXN3015 | C3016: Withdrawal Fee | D3016: 120.55 | E3016: 45957
